[2025-07-28T18:09:13.311+0000] {local_task_job_runner.py:120} INFO - ::group::Pre task execution logs
[2025-07-28T18:09:13.452+0000] {taskinstance.py:2076} INFO - Dependencies all met for dep_context=non-requeueable deps ti=<TaskInstance: jobs_ingest_transform.t2_transform manual__2025-07-28T17:50:25.205466+00:00 [queued]>
[2025-07-28T18:09:13.465+0000] {taskinstance.py:2076} INFO - Dependencies all met for dep_context=requeueable deps ti=<TaskInstance: jobs_ingest_transform.t2_transform manual__2025-07-28T17:50:25.205466+00:00 [queued]>
[2025-07-28T18:09:13.466+0000] {taskinstance.py:2306} INFO - Starting attempt 4 of 4
[2025-07-28T18:09:13.477+0000] {taskinstance.py:2330} INFO - Executing <Task(PythonOperator): t2_transform> on 2025-07-28 17:50:25.205466+00:00
[2025-07-28T18:09:13.488+0000] {standard_task_runner.py:63} INFO - Started process 188 to run task
[2025-07-28T18:09:13.491+0000] {standard_task_runner.py:90} INFO - Running: ['airflow', 'tasks', 'run', 'jobs_ingest_transform', 't2_transform', 'manual__2025-07-28T17:50:25.205466+00:00', '--job-id', '6', '--raw', '--subdir', 'DAGS_FOLDER/jobs_ingest_transform_dag.py', '--cfg-path', '/tmp/tmplzj5udqh']
[2025-07-28T18:09:13.495+0000] {standard_task_runner.py:91} INFO - Job 6: Subtask t2_transform
[2025-07-28T18:09:13.585+0000] {task_command.py:426} INFO - Running <TaskInstance: jobs_ingest_transform.t2_transform manual__2025-07-28T17:50:25.205466+00:00 [running]> on host 890e7b92db67
[2025-07-28T18:09:13.702+0000] {taskinstance.py:2648} INFO - Exporting env vars: AIRFLOW_CTX_DAG_OWNER='Felipe Velez' AIRFLOW_CTX_DAG_ID='jobs_ingest_transform' AIRFLOW_CTX_TASK_ID='t2_transform' AIRFLOW_CTX_EXECUTION_DATE='2025-07-28T17:50:25.205466+00:00' AIRFLOW_CTX_TRY_NUMBER='4' AIRFLOW_CTX_DAG_RUN_ID='manual__2025-07-28T17:50:25.205466+00:00'
[2025-07-28T18:09:13.704+0000] {taskinstance.py:430} INFO - ::endgroup::
[2025-07-28T18:10:11.997+0000] {taskinstance.py:441} INFO - ::group::Post task execution logs
[2025-07-28T18:10:12.000+0000] {taskinstance.py:2905} ERROR - Task failed with exception
Traceback (most recent call last):
  File "/home/airflow/.local/lib/python3.11/site-packages/airflow/models/taskinstance.py", line 465, in _execute_task
    result = _execute_callable(context=context, **execute_callable_kwargs)
             ^^^^^^^^^^^^^^^^^^^^^^^^^^^^^^^^^^^^^^^^^^^^^^^^^^^^^^^^^^^^^
  File "/home/airflow/.local/lib/python3.11/site-packages/airflow/models/taskinstance.py", line 432, in _execute_callable
    return execute_callable(context=context, **execute_callable_kwargs)
           ^^^^^^^^^^^^^^^^^^^^^^^^^^^^^^^^^^^^^^^^^^^^^^^^^^^^^^^^^^^^
  File "/home/airflow/.local/lib/python3.11/site-packages/airflow/models/baseoperator.py", line 400, in wrapper
    return func(self, *args, **kwargs)
           ^^^^^^^^^^^^^^^^^^^^^^^^^^^
  File "/home/airflow/.local/lib/python3.11/site-packages/airflow/operators/python.py", line 235, in execute
    return_value = self.execute_callable()
                   ^^^^^^^^^^^^^^^^^^^^^^^
  File "/home/airflow/.local/lib/python3.11/site-packages/airflow/operators/python.py", line 252, in execute_callable
    return self.python_callable(*self.op_args, **self.op_kwargs)
           ^^^^^^^^^^^^^^^^^^^^^^^^^^^^^^^^^^^^^^^^^^^^^^^^^^^^^
  File "/opt/airflow/scripts/transform_to_3nf.py", line 87, in main
    jobs_df = df.assign(
              ^^^^^^^^^^
  File "/home/airflow/.local/lib/python3.11/site-packages/pandas/core/frame.py", line 3899, in __getitem__
    indexer = self.columns._get_indexer_strict(key, "columns")[1]
              ^^^^^^^^^^^^^^^^^^^^^^^^^^^^^^^^^^^^^^^^^^^^^^^^
  File "/home/airflow/.local/lib/python3.11/site-packages/pandas/core/indexes/base.py", line 6115, in _get_indexer_strict
    self._raise_if_missing(keyarr, indexer, axis_name)
  File "/home/airflow/.local/lib/python3.11/site-packages/pandas/core/indexes/base.py", line 6179, in _raise_if_missing
    raise KeyError(f"{not_found} not in index")
KeyError: "['via', 'work_from_home'] not in index"
[2025-07-28T18:10:12.061+0000] {taskinstance.py:1206} INFO - Marking task as FAILED. dag_id=jobs_ingest_transform, task_id=t2_transform, run_id=manual__2025-07-28T17:50:25.205466+00:00, execution_date=20250728T175025, start_date=20250728T180913, end_date=20250728T181012
[2025-07-28T18:10:12.091+0000] {standard_task_runner.py:110} ERROR - Failed to execute job 6 for task t2_transform ("['via', 'work_from_home'] not in index"; 188)
[2025-07-28T18:10:12.212+0000] {local_task_job_runner.py:240} INFO - Task exited with return code 1
[2025-07-28T18:10:12.304+0000] {taskinstance.py:3498} INFO - 0 downstream tasks scheduled from follow-on schedule check
[2025-07-28T18:10:12.306+0000] {local_task_job_runner.py:222} INFO - ::endgroup::
