[2025-07-28T18:05:42.156+0000] {local_task_job_runner.py:120} INFO - ::group::Pre task execution logs
[2025-07-28T18:05:42.273+0000] {taskinstance.py:2076} INFO - Dependencies all met for dep_context=non-requeueable deps ti=<TaskInstance: jobs_ingest_transform.t2_transform manual__2025-07-28T17:50:25.205466+00:00 [queued]>
[2025-07-28T18:05:42.290+0000] {taskinstance.py:2076} INFO - Dependencies all met for dep_context=requeueable deps ti=<TaskInstance: jobs_ingest_transform.t2_transform manual__2025-07-28T17:50:25.205466+00:00 [queued]>
[2025-07-28T18:05:42.292+0000] {taskinstance.py:2306} INFO - Starting attempt 3 of 4
[2025-07-28T18:05:42.303+0000] {taskinstance.py:2330} INFO - Executing <Task(PythonOperator): t2_transform> on 2025-07-28 17:50:25.205466+00:00
[2025-07-28T18:05:42.309+0000] {standard_task_runner.py:63} INFO - Started process 166 to run task
[2025-07-28T18:05:42.312+0000] {standard_task_runner.py:90} INFO - Running: ['airflow', 'tasks', 'run', 'jobs_ingest_transform', 't2_transform', 'manual__2025-07-28T17:50:25.205466+00:00', '--job-id', '5', '--raw', '--subdir', 'DAGS_FOLDER/jobs_ingest_transform_dag.py', '--cfg-path', '/tmp/tmpyaxlyc1_']
[2025-07-28T18:05:42.314+0000] {standard_task_runner.py:91} INFO - Job 5: Subtask t2_transform
[2025-07-28T18:05:42.421+0000] {task_command.py:426} INFO - Running <TaskInstance: jobs_ingest_transform.t2_transform manual__2025-07-28T17:50:25.205466+00:00 [running]> on host 890e7b92db67
[2025-07-28T18:05:42.544+0000] {taskinstance.py:2648} INFO - Exporting env vars: AIRFLOW_CTX_DAG_OWNER='Felipe Velez' AIRFLOW_CTX_DAG_ID='jobs_ingest_transform' AIRFLOW_CTX_TASK_ID='t2_transform' AIRFLOW_CTX_EXECUTION_DATE='2025-07-28T17:50:25.205466+00:00' AIRFLOW_CTX_TRY_NUMBER='3' AIRFLOW_CTX_DAG_RUN_ID='manual__2025-07-28T17:50:25.205466+00:00'
[2025-07-28T18:05:42.545+0000] {taskinstance.py:430} INFO - ::endgroup::
[2025-07-28T18:07:08.501+0000] {taskinstance.py:441} INFO - ::group::Post task execution logs
[2025-07-28T18:07:08.522+0000] {taskinstance.py:2905} ERROR - Task failed with exception
Traceback (most recent call last):
  File "/home/airflow/.local/lib/python3.11/site-packages/airflow/models/taskinstance.py", line 465, in _execute_task
    result = _execute_callable(context=context, **execute_callable_kwargs)
             ^^^^^^^^^^^^^^^^^^^^^^^^^^^^^^^^^^^^^^^^^^^^^^^^^^^^^^^^^^^^^
  File "/home/airflow/.local/lib/python3.11/site-packages/airflow/models/taskinstance.py", line 432, in _execute_callable
    return execute_callable(context=context, **execute_callable_kwargs)
           ^^^^^^^^^^^^^^^^^^^^^^^^^^^^^^^^^^^^^^^^^^^^^^^^^^^^^^^^^^^^
  File "/home/airflow/.local/lib/python3.11/site-packages/airflow/models/baseoperator.py", line 400, in wrapper
    return func(self, *args, **kwargs)
           ^^^^^^^^^^^^^^^^^^^^^^^^^^^
  File "/home/airflow/.local/lib/python3.11/site-packages/airflow/operators/python.py", line 235, in execute
    return_value = self.execute_callable()
                   ^^^^^^^^^^^^^^^^^^^^^^^
  File "/home/airflow/.local/lib/python3.11/site-packages/airflow/operators/python.py", line 252, in execute_callable
    return self.python_callable(*self.op_args, **self.op_kwargs)
           ^^^^^^^^^^^^^^^^^^^^^^^^^^^^^^^^^^^^^^^^^^^^^^^^^^^^^
  File "/opt/airflow/scripts/transform_to_3nf.py", line 87, in main
    jobs_df = df.assign(
              ^^^^^^^^^^
  File "/home/airflow/.local/lib/python3.11/site-packages/pandas/core/frame.py", line 3899, in __getitem__
    indexer = self.columns._get_indexer_strict(key, "columns")[1]
              ^^^^^^^^^^^^^^^^^^^^^^^^^^^^^^^^^^^^^^^^^^^^^^^^
  File "/home/airflow/.local/lib/python3.11/site-packages/pandas/core/indexes/base.py", line 6115, in _get_indexer_strict
    self._raise_if_missing(keyarr, indexer, axis_name)
  File "/home/airflow/.local/lib/python3.11/site-packages/pandas/core/indexes/base.py", line 6179, in _raise_if_missing
    raise KeyError(f"{not_found} not in index")
KeyError: "['via', 'work_from_home'] not in index"
[2025-07-28T18:07:08.635+0000] {taskinstance.py:1206} INFO - Marking task as UP_FOR_RETRY. dag_id=jobs_ingest_transform, task_id=t2_transform, run_id=manual__2025-07-28T17:50:25.205466+00:00, execution_date=20250728T175025, start_date=20250728T180542, end_date=20250728T180708
[2025-07-28T18:07:08.710+0000] {standard_task_runner.py:110} ERROR - Failed to execute job 5 for task t2_transform ("['via', 'work_from_home'] not in index"; 166)
[2025-07-28T18:07:09.021+0000] {local_task_job_runner.py:240} INFO - Task exited with return code 1
[2025-07-28T18:07:09.210+0000] {taskinstance.py:3498} INFO - 0 downstream tasks scheduled from follow-on schedule check
[2025-07-28T18:07:09.213+0000] {local_task_job_runner.py:222} INFO - ::endgroup::
