[2025-07-28T16:55:25.844+0000] {local_task_job_runner.py:120} INFO - ::group::Pre task execution logs
[2025-07-28T16:55:25.968+0000] {taskinstance.py:2076} INFO - Dependencies all met for dep_context=non-requeueable deps ti=<TaskInstance: jobs_ingest_transform.t2_transform manual__2025-07-28T16:54:34.187368+00:00 [queued]>
[2025-07-28T16:55:25.984+0000] {taskinstance.py:2076} INFO - Dependencies all met for dep_context=requeueable deps ti=<TaskInstance: jobs_ingest_transform.t2_transform manual__2025-07-28T16:54:34.187368+00:00 [queued]>
[2025-07-28T16:55:25.985+0000] {taskinstance.py:2306} INFO - Starting attempt 1 of 2
[2025-07-28T16:55:25.999+0000] {taskinstance.py:2330} INFO - Executing <Task(PythonOperator): t2_transform> on 2025-07-28 16:54:34.187368+00:00
[2025-07-28T16:55:26.007+0000] {standard_task_runner.py:63} INFO - Started process 590 to run task
[2025-07-28T16:55:26.015+0000] {standard_task_runner.py:90} INFO - Running: ['airflow', 'tasks', 'run', 'jobs_ingest_transform', 't2_transform', 'manual__2025-07-28T16:54:34.187368+00:00', '--job-id', '9', '--raw', '--subdir', 'DAGS_FOLDER/jobs_ingest_transform_dag.py', '--cfg-path', '/tmp/tmp62b3euvc']
[2025-07-28T16:55:26.029+0000] {standard_task_runner.py:91} INFO - Job 9: Subtask t2_transform
[2025-07-28T16:55:26.177+0000] {task_command.py:426} INFO - Running <TaskInstance: jobs_ingest_transform.t2_transform manual__2025-07-28T16:54:34.187368+00:00 [running]> on host 0361872d8b87
[2025-07-28T16:55:26.312+0000] {taskinstance.py:2648} INFO - Exporting env vars: AIRFLOW_CTX_DAG_OWNER='Felipe Velez' AIRFLOW_CTX_DAG_ID='jobs_ingest_transform' AIRFLOW_CTX_TASK_ID='t2_transform' AIRFLOW_CTX_EXECUTION_DATE='2025-07-28T16:54:34.187368+00:00' AIRFLOW_CTX_TRY_NUMBER='1' AIRFLOW_CTX_DAG_RUN_ID='manual__2025-07-28T16:54:34.187368+00:00'
[2025-07-28T16:55:26.313+0000] {taskinstance.py:430} INFO - ::endgroup::
[2025-07-28T16:55:43.370+0000] {taskinstance.py:441} INFO - ::group::Post task execution logs
[2025-07-28T16:55:43.372+0000] {taskinstance.py:2905} ERROR - Task failed with exception
Traceback (most recent call last):
  File "/home/airflow/.local/lib/python3.11/site-packages/sqlalchemy/engine/base.py", line 1910, in _execute_context
    self.dialect.do_execute(
  File "/home/airflow/.local/lib/python3.11/site-packages/sqlalchemy/engine/default.py", line 736, in do_execute
    cursor.execute(statement, parameters)
psycopg2.errors.InvalidColumnReference: there is no unique or exclusion constraint matching the ON CONFLICT specification


The above exception was the direct cause of the following exception:

Traceback (most recent call last):
  File "/home/airflow/.local/lib/python3.11/site-packages/airflow/models/taskinstance.py", line 465, in _execute_task
    result = _execute_callable(context=context, **execute_callable_kwargs)
             ^^^^^^^^^^^^^^^^^^^^^^^^^^^^^^^^^^^^^^^^^^^^^^^^^^^^^^^^^^^^^
  File "/home/airflow/.local/lib/python3.11/site-packages/airflow/models/taskinstance.py", line 432, in _execute_callable
    return execute_callable(context=context, **execute_callable_kwargs)
           ^^^^^^^^^^^^^^^^^^^^^^^^^^^^^^^^^^^^^^^^^^^^^^^^^^^^^^^^^^^^
  File "/home/airflow/.local/lib/python3.11/site-packages/airflow/models/baseoperator.py", line 400, in wrapper
    return func(self, *args, **kwargs)
           ^^^^^^^^^^^^^^^^^^^^^^^^^^^
  File "/home/airflow/.local/lib/python3.11/site-packages/airflow/operators/python.py", line 235, in execute
    return_value = self.execute_callable()
                   ^^^^^^^^^^^^^^^^^^^^^^^
  File "/home/airflow/.local/lib/python3.11/site-packages/airflow/operators/python.py", line 252, in execute_callable
    return self.python_callable(*self.op_args, **self.op_kwargs)
           ^^^^^^^^^^^^^^^^^^^^^^^^^^^^^^^^^^^^^^^^^^^^^^^^^^^^^
  File "/opt/airflow/scripts/transform_to_3nf.py", line 37, in main
    map_location = upsert_cat(df, "locations",  "job_location", "raw_location", id_col="location_id")
                   ^^^^^^^^^^^^^^^^^^^^^^^^^^^^^^^^^^^^^^^^^^^^^^^^^^^^^^^^^^^^^^^^^^^^^^^^^^^^^^^^^^
  File "/opt/airflow/scripts/transform_to_3nf.py", line 18, in upsert_cat
    conn.execute(
  File "/home/airflow/.local/lib/python3.11/site-packages/sqlalchemy/engine/base.py", line 1385, in execute
    return meth(self, multiparams, params, _EMPTY_EXECUTION_OPTS)
           ^^^^^^^^^^^^^^^^^^^^^^^^^^^^^^^^^^^^^^^^^^^^^^^^^^^^^^
  File "/home/airflow/.local/lib/python3.11/site-packages/sqlalchemy/sql/elements.py", line 334, in _execute_on_connection
    return connection._execute_clauseelement(
           ^^^^^^^^^^^^^^^^^^^^^^^^^^^^^^^^^^
  File "/home/airflow/.local/lib/python3.11/site-packages/sqlalchemy/engine/base.py", line 1577, in _execute_clauseelement
    ret = self._execute_context(
          ^^^^^^^^^^^^^^^^^^^^^^
  File "/home/airflow/.local/lib/python3.11/site-packages/sqlalchemy/engine/base.py", line 1953, in _execute_context
    self._handle_dbapi_exception(
  File "/home/airflow/.local/lib/python3.11/site-packages/sqlalchemy/engine/base.py", line 2134, in _handle_dbapi_exception
    util.raise_(
  File "/home/airflow/.local/lib/python3.11/site-packages/sqlalchemy/util/compat.py", line 211, in raise_
    raise exception
  File "/home/airflow/.local/lib/python3.11/site-packages/sqlalchemy/engine/base.py", line 1910, in _execute_context
    self.dialect.do_execute(
  File "/home/airflow/.local/lib/python3.11/site-packages/sqlalchemy/engine/default.py", line 736, in do_execute
    cursor.execute(statement, parameters)
sqlalchemy.exc.ProgrammingError: (psycopg2.errors.InvalidColumnReference) there is no unique or exclusion constraint matching the ON CONFLICT specification

[SQL: INSERT INTO locations (raw_location) SELECT unnest(%(vals)s) ON CONFLICT (raw_location) DO NOTHING]
[parameters: {'vals': ['Watertown, CT', 'Guadalajara, Jalisco, Mexico', 'Berlin, Germany', 'San Antonio, TX', 'Washington, DC', 'Anywhere', 'Dearborn, MI', 'Copenhagen, Den ... (414562 characters truncated) ...  Jerman', 'Basel, Swiss', 'Overland Park, Kansas, Amerika Serikat', 'Heidelberg, Jerman', 'Bad Rodach, Jerman', 'Newark, New Jersey, Amerika Serikat']}]
(Background on this error at: https://sqlalche.me/e/14/f405)
[2025-07-28T16:55:43.441+0000] {taskinstance.py:1206} INFO - Marking task as UP_FOR_RETRY. dag_id=jobs_ingest_transform, task_id=t2_transform, run_id=manual__2025-07-28T16:54:34.187368+00:00, execution_date=20250728T165434, start_date=20250728T165525, end_date=20250728T165543
[2025-07-28T16:55:43.467+0000] {standard_task_runner.py:110} ERROR - Failed to execute job 9 for task t2_transform ((psycopg2.errors.InvalidColumnReference) there is no unique or exclusion constraint matching the ON CONFLICT specification

[SQL: INSERT INTO locations (raw_location) SELECT unnest(%(vals)s) ON CONFLICT (raw_location) DO NOTHING]
[parameters: {'vals': ['Watertown, CT', 'Guadalajara, Jalisco, Mexico', 'Berlin, Germany', 'San Antonio, TX', 'Washington, DC', 'Anywhere', 'Dearborn, MI', 'Copenhagen, Den ... (414562 characters truncated) ...  Jerman', 'Basel, Swiss', 'Overland Park, Kansas, Amerika Serikat', 'Heidelberg, Jerman', 'Bad Rodach, Jerman', 'Newark, New Jersey, Amerika Serikat']}]
(Background on this error at: https://sqlalche.me/e/14/f405); 590)
[2025-07-28T16:55:43.552+0000] {local_task_job_runner.py:240} INFO - Task exited with return code 1
[2025-07-28T16:55:43.578+0000] {taskinstance.py:3498} INFO - 0 downstream tasks scheduled from follow-on schedule check
[2025-07-28T16:55:43.580+0000] {local_task_job_runner.py:222} INFO - ::endgroup::
